Workbook

Sheet 📋 Matches
A1: Round | B1: Match | C1: 🏠 | D1: Home Team | E1: Score Home | F1: Score Away | G1: 🚩 | H1: Away Team | I1: Status
A2: R1 | B2: Mexico vs South Africa | C2: 🏠 | D2: Mexico | E2: 2 | F2: 0 | G2: 🚩 | H2: South Africa | I2: ✅ Done
A3: R1 | B3: South Korea vs Czechia | C3: 🏠 | D3: South Korea | E3: 2 | F3: 1 | G3: 🚩 | H3: Czechia | I3: ✅ Done
A4: R1 | B4: Canada vs Bosnia and Herzeg | C4: 🏠 | D4: Canada | E4: 1 | F4: 1 | G4: 🚩 | H4: Bosnia and Herzeg | I4: ✅ Done
A5: R1 | B5: United States vs Paraguay | C5: 🏠 | D5: United States | E5: 4 | F5: 1 | G5: 🚩 | H5: Paraguay | I5: ✅ Done
A6: R1 | B6: Qatar vs Switzerland | C6: 🏠 | D6: Qatar | G6: 🚩 | H6: Switzerland | I6: ⏳ Pending
A7: R1 | B7: Brazil vs Morocco | C7: 🏠 | D7: Brazil | G7: 🚩 | H7: Morocco | I7: ⏳ Pending
A8: R1 | B8: Haiti vs Scotland | C8: 🏠 | D8: Haiti | G8: 🚩 | H8: Scotland | I8: ⏳ Pending
A9: R1 | B9: Australia vs Türkiye | C9: 🏠 | D9: Australia | G9: 🚩 | H9: Türkiye | I9: ⏳ Pending
A10: R1 | B10: Germany vs Curacao | C10: 🏠 | D10: Germany | G10: 🚩 | H10: Curacao | I10: ⏳ Pending
A11: R1 | B11: Netherlands vs Japan | C11: 🏠 | D11: Netherlands | G11: 🚩 | H11: Japan | I11: ⏳ Pending
A12: R1 | B12: Ivory Coast vs Ecuador | C12: 🏠 | D12: Ivory Coast | G12: 🚩 | H12: Ecuador | I12: ⏳ Pending
A13: R1 | B13: Sweden vs Tunisia | C13: 🏠 | D13: Sweden | G13: 🚩 | H13: Tunisia | I13: ⏳ Pending
A14: R1 | B14: Spain vs Cape Verde | C14: 🏠 | D14: Spain | G14: 🚩 | H14: Cape Verde | I14: ⏳ Pending
A15: R1 | B15: Belgium vs Egypt | C15: 🏠 | D15: Belgium | G15: 🚩 | H15: Egypt | I15: ⏳ Pending
A16: R1 | B16: Saudi Arabia vs Uruguay | C16: 🏠 | D16: Saudi Arabia | G16: 🚩 | H16: Uruguay | I16: ⏳ Pending
A17: R1 | B17: Iran vs New Zealand | C17: 🏠 | D17: Iran | G17: 🚩 | H17: New Zealand | I17: ⏳ Pending
... A73: R3 | B73: Jordan vs. Argentina | C73: 🏠 | D73: Jordan | G73: 🚩 | H73: Argentina | I73: ⏳ Pending

Sheet 📊 Predictions
A1: Round | B1: Participant | C1: Match | D1: Pred Home | E1: Pred Away | F1: Score Home | G1: Score Away | H1: 🏆 Win (48pts) | I1: 🎯 Home Goals(15) | J1: 🎯 Away Goals(15) | K1: ↔ Diff (12pts) | L1: Total Points
A2: R1 | B2: Duaij Alsaleh | C2: Mexico vs South Africa | D2: 3 | E2: 1 | F2: ='📋 Matches'!E2 -> 2 | G2: ='📋 Matches'!F2 -> 0 | H2: =IF(AND(ISNUMBER(F2),ISNUMBER(G2)),IF(SIGN(D2-E2)=SIGN(F2-G2),48,0),"") -> 48 | I2: =IF(AND(ISNUMBER(F2),ISNUMBER(G2)),IF(D2=F2,15,0),"") -> 0 | J2: =IF(AND(ISNUMBER(F2),ISNUMBER(G2)),IF(E2=G2,15,0),"") -> 0 | K2: =IF(AND(ISNUMBER(F2),ISNUMBER(G2)),IF(ABS(D2-E2)=ABS(F2-G2),12,0),"") -> 12 | L2: =IF(ISNUMBER(H2),H2+I2+J2+K2,"") -> 60
A3: R1 | B3: Duaij Alsaleh | C3: South Korea vs Czechia | D3: 1 | E3: 2 | F3: ='📋 Matches'!E3 -> 2 | G3: ='📋 Matches'!F3 -> 1 | H3: =IF(AND(ISNUMBER(F3),ISNUMBER(G3)),IF(SIGN(D3-E3)=SIGN(F3-G3),48,0),"") -> 0 | I3: =IF(AND(ISNUMBER(F3),ISNUMBER(G3)),IF(D3=F3,15,0),"") -> 0 | J3: =IF(AND(ISNUMBER(F3),ISNUMBER(G3)),IF(E3=G3,15,0),"") -> 0 | K3: =IF(AND(ISNUMBER(F3),ISNUMBER(G3)),IF(ABS(D3-E3)=ABS(F3-G3),12,0),"") -> 12 | L3: =IF(ISNUMBER(H3),H3+I3+J3+K3,"") -> 12
A4: R1 | B4: Duaij Alsaleh | C4: Canada vs Bosnia and Herzeg | D4: 0 | E4: 2 | F4: ='📋 Matches'!E4 -> 1 | G4: ='📋 Matches'!F4 -> 1 | H4: =IF(AND(ISNUMBER(F4),ISNUMBER(G4)),IF(SIGN(D4-E4)=SIGN(F4-G4),48,0),"") -> 0 | I4: =IF(AND(ISNUMBER(F4),ISNUMBER(G4)),IF(D4=F4,15,0),"") -> 0 | J4: =IF(AND(ISNUMBER(F4),ISNUMBER(G4)),IF(E4=G4,15,0),"") -> 0 | K4: =IF(AND(ISNUMBER(F4),ISNUMBER(G4)),IF(ABS(D4-E4)=ABS(F4-G4),12,0),"") -> 0 | L4: =IF(ISNUMBER(H4),H4+I4+J4+K4,"") -> 0
A5: R1 | B5: Duaij Alsaleh | C5: United States vs Paraguay | D5: 1 | E5: 1 | F5: ='📋 Matches'!E5 -> 4 | G5: ='📋 Matches'!F5 -> 1 | H5: =IF(AND(ISNUMBER(F5),ISNUMBER(G5)),IF(SIGN(D5-E5)=SIGN(F5-G5),48,0),"") -> 0 | I5: =IF(AND(ISNUMBER(F5),ISNUMBER(G5)),IF(D5=F5,15,0),"") -> 0 | J5: =IF(AND(ISNUMBER(F5),ISNUMBER(G5)),IF(E5=G5,15,0),"") -> 15 | K5: =IF(AND(ISNUMBER(F5),ISNUMBER(G5)),IF(ABS(D5-E5)=ABS(F5-G5),12,0),"") -> 0 | L5: =IF(ISNUMBER(H5),H5+I5+J5+K5,"") -> 15
A6: R1 | B6: Duaij Alsaleh | C6: Qatar vs Switzerland | D6: 0 | E6: 4 | F6: ='📋 Matches'!E6 -> 0 | G6: ='📋 Matches'!F6 -> 0 | H6: =IF(AND(ISNUMBER(F6),ISNUMBER(G6)),IF(SIGN(D6-E6)=SIGN(F6-G6),48,0),"") | I6: =IF(AND(ISNUMBER(F6),ISNUMBER(G6)),IF(D6=F6,15,0),"") | J6: =IF(AND(ISNUMBER(F6),ISNUMBER(G6)),IF(E6=G6,15,0),"") | K6: =IF(AND(ISNUMBER(F6),ISNUMBER(G6)),IF(ABS(D6-E6)=ABS(F6-G6),12,0),"") | L6: =IF(ISNUMBER(H6),H6+I6+J6+K6,"")
A7: R1 | B7: Duaij Alsaleh | C7: Brazil vs Morocco | D7: 2 | E7: 1 | F7: ='📋 Matches'!E7 -> 0 | G7: ='📋 Matches'!F7 -> 0 | H7: =IF(AND(ISNUMBER(F7),ISNUMBER(G7)),IF(SIGN(D7-E7)=SIGN(F7-G7),48,0),"") | I7: =IF(AND(ISNUMBER(F7),ISNUMBER(G7)),IF(D7=F7,15,0),"") | J7: =IF(AND(ISNUMBER(F7),ISNUMBER(G7)),IF(E7=G7,15,0),"") | K7: =IF(AND(ISNUMBER(F7),ISNUMBER(G7)),IF(ABS(D7-E7)=ABS(F7-G7),12,0),"") | L7: =IF(ISNUMBER(H7),H7+I7+J7+K7,"")
A8: R1 | B8: Duaij Alsaleh | C8: Haiti vs Scotland | D8: 0 | E8: 6 | F8: ='📋 Matches'!E8 -> 0 | G8: ='📋 Matches'!F8 -> 0 | H8: =IF(AND(ISNUMBER(F8),ISNUMBER(G8)),IF(SIGN(D8-E8)=SIGN(F8-G8),48,0),"") | I8: =IF(AND(ISNUMBER(F8),ISNUMBER(G8)),IF(D8=F8,15,0),"") | J8: =IF(AND(ISNUMBER(F8),ISNUMBER(G8)),IF(E8=G8,15,0),"") | K8: =IF(AND(ISNUMBER(F8),ISNUMBER(G8)),IF(ABS(D8-E8)=ABS(F8-G8),12,0),"") | L8: =IF(ISNUMBER(H8),H8+I8+J8+K8,"")
A9: R1 | B9: Duaij Alsaleh | C9: Australia vs Türkiye | D9: 1 | E9: 3 | F9: ='📋 Matches'!E9 -> 0 | G9: ='📋 Matches'!F9 -> 0 | H9: =IF(AND(ISNUMBER(F9),ISNUMBER(G9)),IF(SIGN(D9-E9)=SIGN(F9-G9),48,0),"") | I9: =IF(AND(ISNUMBER(F9),ISNUMBER(G9)),IF(D9=F9,15,0),"") | J9: =IF(AND(ISNUMBER(F9),ISNUMBER(G9)),IF(E9=G9,15,0),"") | K9: =IF(AND(ISNUMBER(F9),ISNUMBER(G9)),IF(ABS(D9-E9)=ABS(F9-G9),12,0),"") | L9: =IF(ISNUMBER(H9),H9+I9+J9+K9,"")
A10: R1 | B10: Duaij Alsaleh | C10: Germany vs Curacao | D10: 5 | E10: 0 | F10: ='📋 Matches'!E10 -> 0 | G10: ='📋 Matches'!F10 -> 0 | H10: =IF(AND(ISNUMBER(F10),ISNUMBER(G10)),IF(SIGN(D10-E10)=SIGN(F10-G10),48,0),"") | I10: =IF(AND(ISNUMBER(F10),ISNUMBER(G10)),IF(D10=F10,15,0),"") | J10: =IF(AND(ISNUMBER(F10),ISNUMBER(G10)),IF(E10=G10,15,0),"") | K10: =IF(AND(ISNUMBER(F10),ISNUMBER(G10)),IF(ABS(D10-E10)=ABS(F10-G10),12,0),"") | L10: =IF(ISNUMBER(H10),H10+I10+J10+K10,"")
A11: R1 | B11: Duaij Alsaleh | C11: Netherlands vs Japan | D11: 4 | E11: 0 | F11: ='📋 Matches'!E11 -> 0 | G11: ='📋 Matches'!F11 -> 0 | H11: =IF(AND(ISNUMBER(F11),ISNUMBER(G11)),IF(SIGN(D11-E11)=SIGN(F11-G11),48,0),"") | I11: =IF(AND(ISNUMBER(F11),ISNUMBER(G11)),IF(D11=F11,15,0),"") | J11: =IF(AND(ISNUMBER(F11),ISNUMBER(G11)),IF(E11=G11,15,0),"") | K11: =IF(AND(ISNUMBER(F11),ISNUMBER(G11)),IF(ABS(D11-E11)=ABS(F11-G11),12,0),"") | L11: =IF(ISNUMBER(H11),H11+I11+J11+K11,"")
A12: R1 | B12: Duaij Alsaleh | C12: Ivory Coast vs Ecuador | D12: 2 | E12: 1 | F12: ='📋 Matches'!E12 -> 0 | G12: ='📋 Matches'!F12 -> 0 | H12: =IF(AND(ISNUMBER(F12),ISNUMBER(G12)),IF(SIGN(D12-E12)=SIGN(F12-G12),48,0),"") | I12: =IF(AND(ISNUMBER(F12),ISNUMBER(G12)),IF(D12=F12,15,0),"") | J12: =IF(AND(ISNUMBER(F12),ISNUMBER(G12)),IF(E12=G12,15,0),"") | K12: =IF(AND(ISNUMBER(F12),ISNUMBER(G12)),IF(ABS(D12-E12)=ABS(F12-G12),12,0),"") | L12: =IF(ISNUMBER(H12),H12+I12+J12+K12,"")
A13: R1 | B13: Duaij Alsaleh | C13: Sweden vs Tunisia | D13: 1 | E13: 1 | F13: ='📋 Matches'!E13 -> 0 | G13: ='📋 Matches'!F13 -> 0 | H13: =IF(AND(ISNUMBER(F13),ISNUMBER(G13)),IF(SIGN(D13-E13)=SIGN(F13-G13),48,0),"") | I13: =IF(AND(ISNUMBER(F13),ISNUMBER(G13)),IF(D13=F13,15,0),"") | J13: =IF(AND(ISNUMBER(F13),ISNUMBER(G13)),IF(E13=G13,15,0),"") | K13: =IF(AND(ISNUMBER(F13),ISNUMBER(G13)),IF(ABS(D13-E13)=ABS(F13-G13),12,0),"") | L13: =IF(ISNUMBER(H13),H13+I13+J13+K13,"")
... A25: R1 | B25: Duaij Alsaleh | C25: Uzbekistan vs Colombia | D25: 1 | E25: 1 | F25: ='📋 Matches'!E25 -> 0 | G25: ='📋 Matches'!F25 -> 0 | H25: =IF(AND(ISNUMBER(F25),ISNUMBER(G25)),IF(SIGN(D25-E25)=SIGN(F25-G25),48,0),"") | I25: =IF(AND(ISNUMBER(F25),ISNUMBER(G25)),IF(D25=F25,15,0),"") | J25: =IF(AND(ISNUMBER(F25),ISNUMBER(G25)),IF(E25=G25,15,0),"") | K25: =IF(AND(ISNUMBER(F25),ISNUMBER(G25)),IF(ABS(D25-E25)=ABS(F25-G25),12,0),"") | L25: =IF(ISNUMBER(H25),H25+I25+J25+K25,"")
A26: R2 | B26: Duaij Alsaleh | C26: Czech Republic vs. South Africa | F26: ='📋 Matches'!E26 -> 0 | G26: ='📋 Matches'!F26 -> 0 | H26: N/A | I26: N/A | J26: N/A | K26: N/A | L26: N/A
A27: R2 | B27: Duaij Alsaleh | C27: Switzerland vs. Bosnia and Herzegovina | F27: ='📋 Matches'!E27 -> 0 | G27: ='📋 Matches'!F27 -> 0 | H27: N/A | I27: N/A | J27: N/A | K27: N/A | L27: N/A
A28: R2 | B28: Duaij Alsaleh | C28: Canada vs. Qatar | F28: ='📋 Matches'!E28 -> 0 | G28: ='📋 Matches'!F28 -> 0 | H28: N/A | I28: N/A | J28: N/A | K28: N/A | L28: N/A
A29: R2 | B29: Duaij Alsaleh | C29: Mexico vs. South Korea | F29: ='📋 Matches'!E29 -> 0 | G29: ='📋 Matches'!F29 -> 0 | H29: N/A | I29: N/A | J29: N/A | K29: N/A | L29: N/A
A30: R2 | B30: Duaij Alsaleh | C30: United States vs. Australia | F30: ='📋 Matches'!E30 -> 0 | G30: ='📋 Matches'!F30 -> 0 | H30: N/A | I30: N/A | J30: N/A | K30: N/A | L30: N/A
A31: R2 | B31: Duaij Alsaleh | C31: Scotland vs. Morocco | F31: ='📋 Matches'!E31 -> 0 | G31: ='📋 Matches'!F31 -> 0 | H31: N/A | I31: N/A | J31: N/A | K31: N/A | L31: N/A
A32: R2 | B32: Duaij Alsaleh | C32: Brazil vs. Haiti | F32: ='📋 Matches'!E32 -> 0 | G32: ='📋 Matches'!F32 -> 0 | H32: N/A | I32: N/A | J32: N/A | K32: N/A | L32: N/A
A33: R2 | B33: Duaij Alsaleh | C33: Turkey vs. Paraguay | F33: ='📋 Matches'!E33 -> 0 | G33: ='📋 Matches'!F33 -> 0 | H33: N/A | I33: N/A | J33: N/A | K33: N/A | L33: N/A
A34: R2 | B34: Duaij Alsaleh | C34: Netherlands vs. Sweden | F34: ='📋 Matches'!E34 -> 0 | G34: ='📋 Matches'!F34 -> 0 | H34: N/A | I34: N/A | J34: N/A | K34: N/A | L34: N/A
A35: R2 | B35: Duaij Alsaleh | C35: Germany vs. Ivory Coast | F35: ='📋 Matches'!E35 -> 0 | G35: ='📋 Matches'!F35 -> 0 | H35: N/A | I35: N/A | J35: N/A | K35: N/A | L35: N/A
A36: R2 | B36: Duaij Alsaleh | C36: Ecuador vs. Curaçao | F36: ='📋 Matches'!E36 -> 0 | G36: ='📋 Matches'!F36 -> 0 | H36: N/A | I36: N/A | J36: N/A | K36: N/A | L36: N/A
A37: R2 | B37: Duaij Alsaleh | C37: Tunisia vs. Japan | F37: ='📋 Matches'!E37 -> 0 | G37: ='📋 Matches'!F37 -> 0 | H37: N/A | I37: N/A | J37: N/A | K37: N/A | L37: N/A
... A73: R3 | B73: Duaij Alsaleh | C73: Jordan vs. Argentina | F73: ='📋 Matches'!E73 -> 0 | G73: ='📋 Matches'!F73 -> 0 | H73: N/A | I73: N/A | J73: N/A | K73: N/A | L73: N/A
A74: R1 | B74: Sulaiman Alsaleh | C74: Mexico vs South Africa | D74: 2 | E74: 2 | F74: ='📋 Matches'!E2 -> 2 | G74: ='📋 Matches'!F2 -> 0 | H74: =IF(AND(ISNUMBER(F74),ISNUMBER(G74)),IF(SIGN(D74-E74)=SIGN(F74-G74),48,0),"") -> 0 | I74: =IF(AND(ISNUMBER(F74),ISNUMBER(G74)),IF(D74=F74,15,0),"") -> 15 | J74: =IF(AND(ISNUMBER(F74),ISNUMBER(G74)),IF(E74=G74,15,0),"") -> 0 | K74: =IF(AND(ISNUMBER(F74),ISNUMBER(G74)),IF(ABS(D74-E74)=ABS(F74-G74),12,0),"") -> 0 | L74: =IF(ISNUMBER(H74),H74+I74+J74+K74,"") -> 15
A75: R1 | B75: Sulaiman Alsaleh | C75: South Korea vs Czechia | D75: 2 | E75: 0 | F75: ='📋 Matches'!E3 -> 2 | G75: ='📋 Matches'!F3 -> 1 | H75: =IF(AND(ISNUMBER(F75),ISNUMBER(G75)),IF(SIGN(D75-E75)=SIGN(F75-G75),48,0),"") -> 48 | I75: =IF(AND(ISNUMBER(F75),ISNUMBER(G75)),IF(D75=F75,15,0),"") -> 15 | J75: =IF(AND(ISNUMBER(F75),ISNUMBER(G75)),IF(E75=G75,15,0),"") -> 0 | K75: =IF(AND(ISNUMBER(F75),ISNUMBER(G75)),IF(ABS(D75-E75)=ABS(F75-G75),12,0),"") -> 0 | L75: =IF(ISNUMBER(H75),H75+I75+J75+K75,"") -> 63
A76: R1 | B76: Sulaiman Alsaleh | C76: Canada vs Bosnia and Herzeg | D76: 1 | E76: 2 | F76: ='📋 Matches'!E4 -> 1 | G76: ='📋 Matches'!F4 -> 1 | H76: =IF(AND(ISNUMBER(F76),ISNUMBER(G76)),IF(SIGN(D76-E76)=SIGN(F76-G76),48,0),"") -> 0 | I76: =IF(AND(ISNUMBER(F76),ISNUMBER(G76)),IF(D76=F76,15,0),"") -> 15 | J76: =IF(AND(ISNUMBER(F76),ISNUMBER(G76)),IF(E76=G76,15,0),"") -> 0 | K76: =IF(AND(ISNUMBER(F76),ISNUMBER(G76)),IF(ABS(D76-E76)=ABS(F76-G76),12,0),"") -> 0 | L76: =IF(ISNUMBER(H76),H76+I76+J76+K76,"") -> 15
A77: R1 | B77: Sulaiman Alsaleh | C77: United States vs Paraguay | D77: 1 | E77: 2 | F77: ='📋 Matches'!E5 -> 4 | G77: ='📋 Matches'!F5 -> 1 | H77: =IF(AND(ISNUMBER(F77),ISNUMBER(G77)),IF(SIGN(D77-E77)=SIGN(F77-G77),48,0),"") -> 0 | I77: =IF(AND(ISNUMBER(F77),ISNUMBER(G77)),IF(D77=F77,15,0),"") -> 0 | J77: =IF(AND(ISNUMBER(F77),ISNUMBER(G77)),IF(E77=G77,15,0),"") -> 0 | K77: =IF(AND(ISNUMBER(F77),ISNUMBER(G77)),IF(ABS(D77-E77)=ABS(F77-G77),12,0),"") -> 0 | L77: =IF(ISNUMBER(H77),H77+I77+J77+K77,"") -> 0
A78: R1 | B78: Sulaiman Alsaleh | C78: Qatar vs Switzerland | D78: 0 | E78: 3 | F78: ='📋 Matches'!E6 -> 0 | G78: ='📋 Matches'!F6 -> 0 | H78: =IF(AND(ISNUMBER(F78),ISNUMBER(G78)),IF(SIGN(D78-E78)=SIGN(F78-G78),48,0),"") | I78: =IF(AND(ISNUMBER(F78),ISNUMBER(G78)),IF(D78=F78,15,0),"") | J78: =IF(AND(ISNUMBER(F78),ISNUMBER(G78)),IF(E78=G78,15,0),"") | K78: =IF(AND(ISNUMBER(F78),ISNUMBER(G78)),IF(ABS(D78-E78)=ABS(F78-G78),12,0),"") | L78: =IF(ISNUMBER(H78),H78+I78+J78+K78,"")
A79: R1 | B79: Sulaiman Alsaleh | C79: Brazil vs Morocco | D79: 2 | E79: 1 | F79: ='📋 Matches'!E7 -> 0 | G79: ='📋 Matches'!F7 -> 0 | H79: =IF(AND(ISNUMBER(F79),ISNUMBER(G79)),IF(SIGN(D79-E79)=SIGN(F79-G79),48,0),"") | I79: =IF(AND(ISNUMBER(F79),ISNUMBER(G79)),IF(D79=F79,15,0),"") | J79: =IF(AND(ISNUMBER(F79),ISNUMBER(G79)),IF(E79=G79,15,0),"") | K79: =IF(AND(ISNUMBER(F79),ISNUMBER(G79)),IF(ABS(D79-E79)=ABS(F79-G79),12,0),"") | L79: =IF(ISNUMBER(H79),H79+I79+J79+K79,"")
A80: R1 | B80: Sulaiman Alsaleh | C80: Haiti vs Scotland | D80: 0 | E80: 2 | F80: ='📋 Matches'!E8 -> 0 | G80: ='📋 Matches'!F8 -> 0 | H80: =IF(AND(ISNUMBER(F80),ISNUMBER(G80)),IF(SIGN(D80-E80)=SIGN(F80-G80),48,0),"") | I80: =IF(AND(ISNUMBER(F80),ISNUMBER(G80)),IF(D80=F80,15,0),"") | J80: =IF(AND(ISNUMBER(F80),ISNUMBER(G80)),IF(E80=G80,15,0),"") | K80: =IF(AND(ISNUMBER(F80),ISNUMBER(G80)),IF(ABS(D80-E80)=ABS(F80-G80),12,0),"") | L80: =IF(ISNUMBER(H80),H80+I80+J80+K80,"")
A81: R1 | B81: Sulaiman Alsaleh | C81: Australia vs Türkiye | D81: 1 | E81: 0 | F81: ='📋 Matches'!E9 -> 0 | G81: ='📋 Matches'!F9 -> 0 | H81: =IF(AND(ISNUMBER(F81),ISNUMBER(G81)),IF(SIGN(D81-E81)=SIGN(F81-G81),48,0),"") | I81: =IF(AND(ISNUMBER(F81),ISNUMBER(G81)),IF(D81=F81,15,0),"") | J81: =IF(AND(ISNUMBER(F81),ISNUMBER(G81)),IF(E81=G81,15,0),"") | K81: =IF(AND(ISNUMBER(F81),ISNUMBER(G81)),IF(ABS(D81-E81)=ABS(F81-G81),12,0),"") | L81: =IF(ISNUMBER(H81),H81+I81+J81+K81,"")
A82: R1 | B82: Sulaiman Alsaleh | C82: Germany vs Curacao | D82: 4 | E82: 0 | F82: ='📋 Matches'!E10 -> 0 | G82: ='📋 Matches'!F10 -> 0 | H82: =IF(AND(ISNUMBER(F82),ISNUMBER(G82)),IF(SIGN(D82-E82)=SIGN(F82-G82),48,0),"") | I82: =IF(AND(ISNUMBER(F82),ISNUMBER(G82)),IF(D82=F82,15,0),"") | J82: =IF(AND(ISNUMBER(F82),ISNUMBER(G82)),IF(E82=G82,15,0),"") | K82: =IF(AND(ISNUMBER(F82),ISNUMBER(G82)),IF(ABS(D82-E82)=ABS(F82-G82),12,0),"") | L82: =IF(ISNUMBER(H82),H82+I82+J82+K82,"")
A83: R1 | B83: Sulaiman Alsaleh | C83: Netherlands vs Japan | D83: 2 | E83: 0 | F83: ='📋 Matches'!E11 -> 0 | G83: ='📋 Matches'!F11 -> 0 | H83: =IF(AND(ISNUMBER(F83),ISNUMBER(G83)),IF(SIGN(D83-E83)=SIGN(F83-G83),48,0),"") | I83: =IF(AND(ISNUMBER(F83),ISNUMBER(G83)),IF(D83=F83,15,0),"") | J83: =IF(AND(ISNUMBER(F83),ISNUMBER(G83)),IF(E83=G83,15,0),"") | K83: =IF(AND(ISNUMBER(F83),ISNUMBER(G83)),IF(ABS(D83-E83)=ABS(F83-G83),12,0),"") | L83: =IF(ISNUMBER(H83),H83+I83+J83+K83,"")
A84: R1 | B84: Sulaiman Alsaleh | C84: Ivory Coast vs Ecuador | D84: 2 | E84: 3 | F84: ='📋 Matches'!E12 -> 0 | G84: ='📋 Matches'!F12 -> 0 | H84: =IF(AND(ISNUMBER(F84),ISNUMBER(G84)),IF(SIGN(D84-E84)=SIGN(F84-G84),48,0),"") | I84: =IF(AND(ISNUMBER(F84),ISNUMBER(G84)),IF(D84=F84,15,0),"") | J84: =IF(AND(ISNUMBER(F84),ISNUMBER(G84)),IF(E84=G84,15,0),"") | K84: =IF(AND(ISNUMBER(F84),ISNUMBER(G84)),IF(ABS(D84-E84)=ABS(F84-G84),12,0),"") | L84: =IF(ISNUMBER(H84),H84+I84+J84+K84,"")
A85: R1 | B85: Sulaiman Alsaleh | C85: Sweden vs Tunisia | D85: 0 | E85: 2 | F85: ='📋 Matches'!E13 -> 0 | G85: ='📋 Matches'!F13 -> 0 | H85: =IF(AND(ISNUMBER(F85),ISNUMBER(G85)),IF(SIGN(D85-E85)=SIGN(F85-G85),48,0),"") | I85: =IF(AND(ISNUMBER(F85),ISNUMBER(G85)),IF(D85=F85,15,0),"") | J85: =IF(AND(ISNUMBER(F85),ISNUMBER(G85)),IF(E85=G85,15,0),"") | K85: =IF(AND(ISNUMBER(F85),ISNUMBER(G85)),IF(ABS(D85-E85)=ABS(F85-G85),12,0),"") | L85: =IF(ISNUMBER(H85),H85+I85+J85+K85,"")
... A97: R1 | B97: Sulaiman Alsaleh | C97: Uzbekistan vs Colombia | D97: 0 | E97: 1 | F97: ='📋 Matches'!E25 -> 0 | G97: ='📋 Matches'!F25 -> 0 | H97: =IF(AND(ISNUMBER(F97),ISNUMBER(G97)),IF(SIGN(D97-E97)=SIGN(F97-G97),48,0),"") | I97: =IF(AND(ISNUMBER(F97),ISNUMBER(G97)),IF(D97=F97,15,0),"") | J97: =IF(AND(ISNUMBER(F97),ISNUMBER(G97)),IF(E97=G97,15,0),"") | K97: =IF(AND(ISNUMBER(F97),ISNUMBER(G97)),IF(ABS(D97-E97)=ABS(F97-G97),12,0),"") | L97: =IF(ISNUMBER(H97),H97+I97+J97+K97,"")
...

Sheet 🏆 Leaderboard
A1: Rank | B1: Participant | C1: Total Points | D1: Win Pts | E1: Home Goal Pts | F1: Away Goal Pts | G1: Diff Pts | H1: Matches Scored
A2: 1 | B2: Duaij Alsaleh | C2: =IFERROR(SUMIF('📊 Predictions'!B:B,B2,'📊 Predictions'!L:L),0) -> 87 | D2: =IFERROR(SUMIF('📊 Predictions'!B:B,B2,'📊 Predictions'!H:H),0) -> 48 | E2: =IFERROR(SUMIF('📊 Predictions'!B:B,B2,'📊 Predictions'!I:I),0) -> 0 | F2: =IFERROR(SUMIF('📊 Predictions'!B:B,B2,'📊 Predictions'!J:J),0) -> 15 | G2: =IFERROR(SUMIF('📊 Predictions'!B:B,B2,'📊 Predictions'!K:K),0) -> 24 | H2: =IFERROR(COUNTIF('📊 Predictions'!B:B,B2),0) -> 72
A3: 2 | B3: Sulaiman Alsaleh | C3: =IFERROR(SUMIF('📊 Predictions'!B:B,B3,'📊 Predictions'!L:L),0) -> 93 | D3: =IFERROR(SUMIF('📊 Predictions'!B:B,B3,'📊 Predictions'!H:H),0) -> 48 | E3: =IFERROR(SUMIF('📊 Predictions'!B:B,B3,'📊 Predictions'!I:I),0) -> 45 | F3: =IFERROR(SUMIF('📊 Predictions'!B:B,B3,'📊 Predictions'!J:J),0) -> 0 | G3: =IFERROR(SUMIF('📊 Predictions'!B:B,B3,'📊 Predictions'!K:K),0) -> 0 | H3: =IFERROR(COUNTIF('📊 Predictions'!B:B,B3),0) -> 72
A4: 3 | B4: HJS Alsaleh | C4: =IFERROR(SUMIF('📊 Predictions'!B:B,B4,'📊 Predictions'!L:L),0) -> 90 | D4: =IFERROR(SUMIF('📊 Predictions'!B:B,B4,'📊 Predictions'!H:H),0) -> 48 | E4: =IFERROR(SUMIF('📊 Predictions'!B:B,B4,'📊 Predictions'!I:I),0) -> 15 | F4: =IFERROR(SUMIF('📊 Predictions'!B:B,B4,'📊 Predictions'!J:J),0) -> 15 | G4: =IFERROR(SUMIF('📊 Predictions'!B:B,B4,'📊 Predictions'!K:K),0) -> 12 | H4: =IFERROR(COUNTIF('📊 Predictions'!B:B,B4),0) -> 72
A5: 4 | B5: Dana | C5: =IFERROR(SUMIF('📊 Predictions'!B:B,B5,'📊 Predictions'!L:L),0) -> 204 | D5: =IFERROR(SUMIF('📊 Predictions'!B:B,B5,'📊 Predictions'!H:H),0) -> 144 | E5: =IFERROR(SUMIF('📊 Predictions'!B:B,B5,'📊 Predictions'!I:I),0) -> 30 | F5: =IFERROR(SUMIF('📊 Predictions'!B:B,B5,'📊 Predictions'!J:J),0) -> 30 | G5: =IFERROR(SUMIF('📊 Predictions'!B:B,B5,'📊 Predictions'!K:K),0) -> 0 | H5: =IFERROR(COUNTIF('📊 Predictions'!B:B,B5),0) -> 72
A6: 5 | B6: عبدالعزيز بوشهري | C6: =IFERROR(SUMIF('📊 Predictions'!B:B,B6,'📊 Predictions'!L:L),0) -> 183 | D6: =IFERROR(SUMIF('📊 Predictions'!B:B,B6,'📊 Predictions'!H:H),0) -> 96 | E6: =IFERROR(SUMIF('📊 Predictions'!B:B,B6,'📊 Predictions'!I:I),0) -> 15 | F6: =IFERROR(SUMIF('📊 Predictions'!B:B,B6,'📊 Predictions'!J:J),0) -> 60 | G6: =IFERROR(SUMIF('📊 Predictions'!B:B,B6,'📊 Predictions'!K:K),0) -> 12 | H6: =IFERROR(COUNTIF('📊 Predictions'!B:B,B6),0) -> 72
A7: 6 | B7: Mohammad Alsaleh | C7: =IFERROR(SUMIF('📊 Predictions'!B:B,B7,'📊 Predictions'!L:L),0) -> 153 | D7: =IFERROR(SUMIF('📊 Predictions'!B:B,B7,'📊 Predictions'!H:H),0) -> 96 | E7: =IFERROR(SUMIF('📊 Predictions'!B:B,B7,'📊 Predictions'!I:I),0) -> 30 | F7: =IFERROR(SUMIF('📊 Predictions'!B:B,B7,'📊 Predictions'!J:J),0) -> 15 | G7: =IFERROR(SUMIF('📊 Predictions'!B:B,B7,'📊 Predictions'!K:K),0) -> 12 | H7: =IFERROR(COUNTIF('📊 Predictions'!B:B,B7),0) -> 72
A8: 7 | B8: Dalal Abuhaimed | C8: =IFERROR(SUMIF('📊 Predictions'!B:B,B8,'📊 Predictions'!L:L),0) -> 105 | D8: =IFERROR(SUMIF('📊 Predictions'!B:B,B8,'📊 Predictions'!H:H),0) -> 48 | E8: =IFERROR(SUMIF('📊 Predictions'!B:B,B8,'📊 Predictions'!I:I),0) -> 15 | F8: =IFERROR(SUMIF('📊 Predictions'!B:B,B8,'📊 Predictions'!J:J),0) -> 30 | G8: =IFERROR(SUMIF('📊 Predictions'!B:B,B8,'📊 Predictions'!K:K),0) -> 12 | H8: =IFERROR(COUNTIF('📊 Predictions'!B:B,B8),0) -> 72
A9: 8 | B9: منيرة (حمد الصالح ) | C9: =IFERROR(SUMIF('📊 Predictions'!B:B,B9,'📊 Predictions'!L:L),0) -> 243 | D9: =IFERROR(SUMIF('📊 Predictions'!B:B,B9,'📊 Predictions'!H:H),0) -> 144 | E9: =IFERROR(SUMIF('📊 Predictions'!B:B,B9,'📊 Predictions'!I:I),0) -> 30 | F9: =IFERROR(SUMIF('📊 Predictions'!B:B,B9,'📊 Predictions'!J:J),0) -> 45 | G9: =IFERROR(SUMIF('📊 Predictions'!B:B,B9,'📊 Predictions'!K:K),0) -> 24 | H9: =IFERROR(COUNTIF('📊 Predictions'!B:B,B9),0) -> 72
A10: 9 | B10: فهد الصالح | C10: =IFERROR(SUMIF('📊 Predictions'!B:B,B10,'📊 Predictions'!L:L),0) -> 135 | D10: =IFERROR(SUMIF('📊 Predictions'!B:B,B10,'📊 Predictions'!H:H),0) -> 96 | E10: =IFERROR(SUMIF('📊 Predictions'!B:B,B10,'📊 Predictions'!I:I),0) -> 15 | F10: =IFERROR(SUMIF('📊 Predictions'!B:B,B10,'📊 Predictions'!J:J),0) -> 0 | G10: =IFERROR(SUMIF('📊 Predictions'!B:B,B10,'📊 Predictions'!K:K),0) -> 24 | H10: =IFERROR(COUNTIF('📊 Predictions'!B:B,B10),0) -> 72
A11: 10 | B11: Saud Alsaleh | C11: =IFERROR(SUMIF('📊 Predictions'!B:B,B11,'📊 Predictions'!L:L),0) -> 183 | D11: =IFERROR(SUMIF('📊 Predictions'!B:B,B11,'📊 Predictions'!H:H),0) -> 96 | E11: =IFERROR(SUMIF('📊 Predictions'!B:B,B11,'📊 Predictions'!I:I),0) -> 15 | F11: =IFERROR(SUMIF('📊 Predictions'!B:B,B11,'📊 Predictions'!J:J),0) -> 60 | G11: =IFERROR(SUMIF('📊 Predictions'!B:B,B11,'📊 Predictions'!K:K),0) -> 12 | H11: =IFERROR(COUNTIF('📊 Predictions'!B:B,B11),0) -> 72
A12: 11 | B12: Fai Khalid | C12: =IFERROR(SUMIF('📊 Predictions'!B:B,B12,'📊 Predictions'!L:L),0) -> 93 | D12: =IFERROR(SUMIF('📊 Predictions'!B:B,B12,'📊 Predictions'!H:H),0) -> 48 | E12: =IFERROR(SUMIF('📊 Predictions'!B:B,B12,'📊 Predictions'!I:I),0) -> 15 | F12: =IFERROR(SUMIF('📊 Predictions'!B:B,B12,'📊 Predictions'!J:J),0) -> 30 | G12: =IFERROR(SUMIF('📊 Predictions'!B:B,B12,'📊 Predictions'!K:K),0) -> 0 | H12: =IFERROR(COUNTIF('📊 Predictions'!B:B,B12),0) -> 72
A13: 12 | B13: bader R. | C13: =IFERROR(SUMIF('📊 Predictions'!B:B,B13,'📊 Predictions'!L:L),0) -> 183 | D13: =IFERROR(SUMIF('📊 Predictions'!B:B,B13,'📊 Predictions'!H:H),0) -> 96 | E13: =IFERROR(SUMIF('📊 Predictions'!B:B,B13,'📊 Predictions'!I:I),0) -> 30 | F13: =IFERROR(SUMIF('📊 Predictions'!B:B,B13,'📊 Predictions'!J:J),0) -> 45 | G13: =IFERROR(SUMIF('📊 Predictions'!B:B,B13,'📊 Predictions'!K:K),0) -> 12 | H13: =IFERROR(COUNTIF('📊 Predictions'!B:B,B13),0) -> 72
... A63: 62 | B63: خليفة بولند | C63: =IFERROR(SUMIF('📊 Predictions'!B:B,B63,'📊 Predictions'!L:L),0) -> 135 | D63: =IFERROR(SUMIF('📊 Predictions'!B:B,B63,'📊 Predictions'!H:H),0) -> 96 | E63: =IFERROR(SUMIF('📊 Predictions'!B:B,B63,'📊 Predictions'!I:I),0) -> 0 | F63: =IFERROR(SUMIF('📊 Predictions'!B:B,B63,'📊 Predictions'!J:J),0) -> 15 | G63: =IFERROR(SUMIF('📊 Predictions'!B:B,B63,'📊 Predictions'!K:K),0) -> 24 | H63: =IFERROR(COUNTIF('📊 Predictions'!B:B,B63),0) -> 72
A65: ⚠️ Re-sort by Column C (Total Points) descending after each score update
